[0m00:53:20.764819 [debug] [MainThread]: Sending event: {'category': 'dbt', 'action': 'invocation', 'label': 'start', 'context': [<snowplow_tracker.self_describing_json.SelfDescribingJson object at 0x0000024B40F50D70>, <snowplow_tracker.self_describing_json.SelfDescribingJson object at 0x0000024B3ED8CB90>, <snowplow_tracker.self_describing_json.SelfDescribingJson object at 0x0000024B4204BED0>]}


============================== 00:53:20.769502 | aa394a33-04de-4f4b-899c-5f1a8c71fd07 ==============================
[0m00:53:20.769502 [info ] [MainThread]: Running with dbt=1.9.2
[0m00:53:20.770216 [debug] [MainThread]: running dbt with arguments {'printer_width': '80', 'indirect_selection': 'eager', 'log_cache_events': 'False', 'write_json': 'True', 'partial_parse': 'True', 'cache_selected_only': 'False', 'profiles_dir': 'C:\\Users\\henri\\.dbt', 'fail_fast': 'False', 'debug': 'False', 'log_path': 'logs', 'warn_error': 'None', 'version_check': 'True', 'use_colors': 'True', 'use_experimental_parser': 'False', 'empty': 'None', 'quiet': 'False', 'no_print': 'None', 'log_format': 'default', 'static_parser': 'True', 'warn_error_options': 'WarnErrorOptions(include=[], exclude=[])', 'introspect': 'True', 'target_path': 'None', 'invocation_command': 'dbt init carteira', 'send_anonymous_usage_stats': 'True'}
[0m00:53:20.787566 [warn ] [MainThread]: [ConfigFolderDirectory]: Unable to parse logging event dictionary. Failed to parse dir field: expected string or bytes-like object, got 'WindowsPath'.. Dictionary: {'dir': WindowsPath('C:/Users/henri/.dbt')}
[0m00:53:20.788110 [info ] [MainThread]: Creating dbt configuration folder at 
[0m00:53:20.790069 [debug] [MainThread]: Starter project path: C:\Users\henri\anaconda3\envs\carteira\Lib\site-packages\dbt\include\starter_project
[0m00:53:20.810384 [info ] [MainThread]: 
Your new dbt project "carteira" was created!

For more information on how to configure the profiles.yml file,
please consult the dbt documentation here:

  https://docs.getdbt.com/docs/configure-your-profile

One more thing:

Need help? Don't hesitate to reach out to us via GitHub issues or on Slack:

  https://community.getdbt.com/

Happy modeling!

[0m00:53:20.811057 [info ] [MainThread]: Setting up your profile.
[0m00:59:22.126313 [error] [MainThread]: Encountered an error:
mapping values are not allowed here
  in "C:\Users\henri\.dbt\profiles.yml", line 3, column 12
[0m00:59:22.134442 [error] [MainThread]: Traceback (most recent call last):
  File "C:\Users\henri\anaconda3\envs\carteira\Lib\site-packages\dbt\cli\requires.py", line 153, in wrapper
    result, success = func(*args, **kwargs)
                      ~~~~^^^^^^^^^^^^^^^^^
  File "C:\Users\henri\anaconda3\envs\carteira\Lib\site-packages\dbt\cli\requires.py", line 103, in wrapper
    return func(*args, **kwargs)
  File "C:\Users\henri\anaconda3\envs\carteira\Lib\site-packages\dbt\cli\main.py", line 477, in init
    results = task.run()
  File "C:\Users\henri\anaconda3\envs\carteira\Lib\site-packages\dbt\task\init.py", line 346, in run
    self.setup_profile(profile_name)
    ~~~~~~~~~~~~~~~~~~^^^^^^^^^^^^^^
  File "C:\Users\henri\anaconda3\envs\carteira\Lib\site-packages\dbt\task\init.py", line 262, in setup_profile
    self.create_profile_from_target(adapter, profile_name=profile_name)
    ~~~~~~~~~~~~~~~~~~~~~~~~~~~~~~~^^^^^^^^^^^^^^^^^^^^^^^^^^^^^^^^^^^^
  File "C:\Users\henri\anaconda3\envs\carteira\Lib\site-packages\dbt\task\init.py", line 179, in create_profile_from_target
    self.create_profile_from_profile_template(profile_template, profile_name)
    ~~~~~~~~~~~~~~~~~~~~~~~~~~~~~~~~~~~~~~~~~^^^^^^^^^^^^^^^^^^^^^^^^^^^^^^^^
  File "C:\Users\henri\anaconda3\envs\carteira\Lib\site-packages\dbt\task\init.py", line 166, in create_profile_from_profile_template
    self.write_profile(profile, profile_name)
    ~~~~~~~~~~~~~~~~~~^^^^^^^^^^^^^^^^^^^^^^^
  File "C:\Users\henri\anaconda3\envs\carteira\Lib\site-packages\dbt\task\init.py", line 152, in write_profile
    profiles = yaml.safe_load(f) or {}
               ~~~~~~~~~~~~~~^^^
  File "C:\Users\henri\anaconda3\envs\carteira\Lib\site-packages\yaml\__init__.py", line 125, in safe_load
    return load(stream, SafeLoader)
  File "C:\Users\henri\anaconda3\envs\carteira\Lib\site-packages\yaml\__init__.py", line 81, in load
    return loader.get_single_data()
           ~~~~~~~~~~~~~~~~~~~~~~^^
  File "C:\Users\henri\anaconda3\envs\carteira\Lib\site-packages\yaml\constructor.py", line 49, in get_single_data
    node = self.get_single_node()
  File "C:\Users\henri\anaconda3\envs\carteira\Lib\site-packages\yaml\composer.py", line 36, in get_single_node
    document = self.compose_document()
  File "C:\Users\henri\anaconda3\envs\carteira\Lib\site-packages\yaml\composer.py", line 55, in compose_document
    node = self.compose_node(None, None)
  File "C:\Users\henri\anaconda3\envs\carteira\Lib\site-packages\yaml\composer.py", line 84, in compose_node
    node = self.compose_mapping_node(anchor)
  File "C:\Users\henri\anaconda3\envs\carteira\Lib\site-packages\yaml\composer.py", line 133, in compose_mapping_node
    item_value = self.compose_node(node, item_key)
  File "C:\Users\henri\anaconda3\envs\carteira\Lib\site-packages\yaml\composer.py", line 84, in compose_node
    node = self.compose_mapping_node(anchor)
  File "C:\Users\henri\anaconda3\envs\carteira\Lib\site-packages\yaml\composer.py", line 127, in compose_mapping_node
    while not self.check_event(MappingEndEvent):
              ~~~~~~~~~~~~~~~~^^^^^^^^^^^^^^^^^
  File "C:\Users\henri\anaconda3\envs\carteira\Lib\site-packages\yaml\parser.py", line 98, in check_event
    self.current_event = self.state()
                         ~~~~~~~~~~^^
  File "C:\Users\henri\anaconda3\envs\carteira\Lib\site-packages\yaml\parser.py", line 428, in parse_block_mapping_key
    if self.check_token(KeyToken):
       ~~~~~~~~~~~~~~~~^^^^^^^^^^
  File "C:\Users\henri\anaconda3\envs\carteira\Lib\site-packages\yaml\scanner.py", line 116, in check_token
    self.fetch_more_tokens()
    ~~~~~~~~~~~~~~~~~~~~~~^^
  File "C:\Users\henri\anaconda3\envs\carteira\Lib\site-packages\yaml\scanner.py", line 223, in fetch_more_tokens
    return self.fetch_value()
           ~~~~~~~~~~~~~~~~^^
  File "C:\Users\henri\anaconda3\envs\carteira\Lib\site-packages\yaml\scanner.py", line 577, in fetch_value
    raise ScannerError(None, None,
            "mapping values are not allowed here",
            self.get_mark())
yaml.scanner.ScannerError: mapping values are not allowed here
  in "C:\Users\henri\.dbt\profiles.yml", line 3, column 12

[0m00:59:22.136221 [debug] [MainThread]: Command `dbt init` failed at 00:59:22.136075 after 361.51 seconds
[0m00:59:22.136622 [debug] [MainThread]: Sending event: {'category': 'dbt', 'action': 'invocation', 'label': 'end', 'context': [<snowplow_tracker.self_describing_json.SelfDescribingJson object at 0x0000024B42201480>, <snowplow_tracker.self_describing_json.SelfDescribingJson object at 0x0000024B4219B890>, <snowplow_tracker.self_describing_json.SelfDescribingJson object at 0x0000024B420FDF20>]}
[0m00:59:22.137049 [debug] [MainThread]: Flushing usage events
[0m00:59:22.876635 [debug] [MainThread]: An error was encountered while trying to flush usage events
[0m00:59:38.268988 [debug] [MainThread]: Sending event: {'category': 'dbt', 'action': 'invocation', 'label': 'start', 'context': [<snowplow_tracker.self_describing_json.SelfDescribingJson object at 0x0000027D375E0D70>, <snowplow_tracker.self_describing_json.SelfDescribingJson object at 0x0000027D386B2990>, <snowplow_tracker.self_describing_json.SelfDescribingJson object at 0x0000027D386B2AD0>]}


============================== 00:59:38.273337 | 2bc9445c-bd61-4732-b5d0-045a68ff73dc ==============================
[0m00:59:38.273337 [info ] [MainThread]: Running with dbt=1.9.2
[0m00:59:38.273999 [debug] [MainThread]: running dbt with arguments {'printer_width': '80', 'indirect_selection': 'eager', 'write_json': 'True', 'log_cache_events': 'False', 'partial_parse': 'True', 'cache_selected_only': 'False', 'warn_error': 'None', 'fail_fast': 'False', 'version_check': 'True', 'log_path': 'logs', 'profiles_dir': 'C:\\Users\\henri\\.dbt', 'debug': 'False', 'use_colors': 'True', 'use_experimental_parser': 'False', 'empty': 'None', 'quiet': 'False', 'no_print': 'None', 'warn_error_options': 'WarnErrorOptions(include=[], exclude=[])', 'invocation_command': 'dbt debug', 'static_parser': 'True', 'log_format': 'default', 'target_path': 'None', 'introspect': 'True', 'send_anonymous_usage_stats': 'True'}
[0m00:59:38.296256 [info ] [MainThread]: dbt version: 1.9.2
[0m00:59:38.296797 [info ] [MainThread]: python version: 3.13.1
[0m00:59:38.297205 [info ] [MainThread]: python path: C:\Users\henri\anaconda3\envs\carteira\python.exe
[0m00:59:38.297577 [info ] [MainThread]: os info: Windows-11-10.0.26100-SP0
[0m00:59:38.298252 [error] [MainThread]: Encountered an error:
Runtime Error
  Syntax error near line 3
  ------------------------------
  1  | carteira:
  2  |   target: prod
  3  |     outputs:
  4  |     type: postgres
  5  |     host: "{{ env_var('PG_URL') }}"
  6  |     user: "{{ env_var('PG_USER') }}"
  
  Raw Error:
  ------------------------------
  mapping values are not allowed in this context
    in "<unicode string>", line 3, column 12
[0m00:59:38.299259 [debug] [MainThread]: Command `dbt debug` failed at 00:59:38.299140 after 0.12 seconds
[0m00:59:38.299597 [debug] [MainThread]: Sending event: {'category': 'dbt', 'action': 'invocation', 'label': 'end', 'context': [<snowplow_tracker.self_describing_json.SelfDescribingJson object at 0x0000027D38768D60>, <snowplow_tracker.self_describing_json.SelfDescribingJson object at 0x0000027D385C97F0>, <snowplow_tracker.self_describing_json.SelfDescribingJson object at 0x0000027D3859E8B0>]}
[0m00:59:38.299964 [debug] [MainThread]: Flushing usage events
[0m00:59:38.891386 [debug] [MainThread]: An error was encountered while trying to flush usage events
[0m01:00:22.397834 [debug] [MainThread]: Sending event: {'category': 'dbt', 'action': 'invocation', 'label': 'start', 'context': [<snowplow_tracker.self_describing_json.SelfDescribingJson object at 0x000002445A740D70>, <snowplow_tracker.self_describing_json.SelfDescribingJson object at 0x000002445B80E990>, <snowplow_tracker.self_describing_json.SelfDescribingJson object at 0x000002445B80EAD0>]}


============================== 01:00:22.402167 | 5b7381cd-d676-4a04-a22c-b5d3eff02c99 ==============================
[0m01:00:22.402167 [info ] [MainThread]: Running with dbt=1.9.2
[0m01:00:22.402738 [debug] [MainThread]: running dbt with arguments {'printer_width': '80', 'indirect_selection': 'eager', 'log_cache_events': 'False', 'write_json': 'True', 'partial_parse': 'True', 'cache_selected_only': 'False', 'warn_error': 'None', 'version_check': 'True', 'debug': 'False', 'log_path': 'logs', 'profiles_dir': 'C:\\Users\\henri\\.dbt', 'fail_fast': 'False', 'use_colors': 'True', 'use_experimental_parser': 'False', 'empty': 'None', 'quiet': 'False', 'no_print': 'None', 'warn_error_options': 'WarnErrorOptions(include=[], exclude=[])', 'introspect': 'True', 'static_parser': 'True', 'invocation_command': 'dbt debug', 'target_path': 'None', 'log_format': 'default', 'send_anonymous_usage_stats': 'True'}
[0m01:00:22.422918 [info ] [MainThread]: dbt version: 1.9.2
[0m01:00:22.423395 [info ] [MainThread]: python version: 3.13.1
[0m01:00:22.423749 [info ] [MainThread]: python path: C:\Users\henri\anaconda3\envs\carteira\python.exe
[0m01:00:22.424075 [info ] [MainThread]: os info: Windows-11-10.0.26100-SP0
[0m01:00:22.424723 [error] [MainThread]: Encountered an error:
Runtime Error
  Syntax error near line 3
  ------------------------------
  1  | carteira:
  2  |   target: prod
  3  |     outputs:
  4  |     type: postgres
  5  |     host: "{{ env_var('PG_URL') }}"
  6  |     user: "{{ env_var('PG_USER') }}"
  
  Raw Error:
  ------------------------------
  mapping values are not allowed in this context
    in "<unicode string>", line 3, column 12
[0m01:00:22.425786 [debug] [MainThread]: Command `dbt debug` failed at 01:00:22.425658 after 0.09 seconds
[0m01:00:22.426185 [debug] [MainThread]: Sending event: {'category': 'dbt', 'action': 'invocation', 'label': 'end', 'context': [<snowplow_tracker.self_describing_json.SelfDescribingJson object at 0x000002445B8BCD60>, <snowplow_tracker.self_describing_json.SelfDescribingJson object at 0x000002445B7297F0>, <snowplow_tracker.self_describing_json.SelfDescribingJson object at 0x000002445B7028B0>]}
[0m01:00:22.426562 [debug] [MainThread]: Flushing usage events
[0m01:00:23.056300 [debug] [MainThread]: An error was encountered while trying to flush usage events
[0m01:00:48.352677 [debug] [MainThread]: Sending event: {'category': 'dbt', 'action': 'invocation', 'label': 'start', 'context': [<snowplow_tracker.self_describing_json.SelfDescribingJson object at 0x000001B663D40D70>, <snowplow_tracker.self_describing_json.SelfDescribingJson object at 0x000001B664E22990>, <snowplow_tracker.self_describing_json.SelfDescribingJson object at 0x000001B664E22AD0>]}


============================== 01:00:48.356902 | dcdd1c33-5042-40bc-b48c-ef87564f0a1c ==============================
[0m01:00:48.356902 [info ] [MainThread]: Running with dbt=1.9.2
[0m01:00:48.357496 [debug] [MainThread]: running dbt with arguments {'printer_width': '80', 'indirect_selection': 'eager', 'log_cache_events': 'False', 'write_json': 'True', 'partial_parse': 'True', 'cache_selected_only': 'False', 'profiles_dir': 'C:\\Users\\henri\\.dbt', 'debug': 'False', 'warn_error': 'None', 'log_path': 'logs', 'version_check': 'True', 'fail_fast': 'False', 'use_colors': 'True', 'use_experimental_parser': 'False', 'no_print': 'None', 'quiet': 'False', 'empty': 'None', 'log_format': 'default', 'introspect': 'True', 'warn_error_options': 'WarnErrorOptions(include=[], exclude=[])', 'invocation_command': 'dbt debug', 'target_path': 'None', 'static_parser': 'True', 'send_anonymous_usage_stats': 'True'}
[0m01:00:48.378551 [info ] [MainThread]: dbt version: 1.9.2
[0m01:00:48.379009 [info ] [MainThread]: python version: 3.13.1
[0m01:00:48.379370 [info ] [MainThread]: python path: C:\Users\henri\anaconda3\envs\carteira\python.exe
[0m01:00:48.379711 [info ] [MainThread]: os info: Windows-11-10.0.26100-SP0
[0m01:00:48.380333 [error] [MainThread]: Encountered an error:
Runtime Error
  Syntax error near line 3
  ------------------------------
  1  | carteira:
  2  |   target: prod
  3  |     outputs:
  4  |       prod:
  5  |         type: postgres
  6  |         host: "{{ env_var('PG_URL') }}"
  
  Raw Error:
  ------------------------------
  mapping values are not allowed in this context
    in "<unicode string>", line 3, column 12
[0m01:00:48.381335 [debug] [MainThread]: Command `dbt debug` failed at 01:00:48.381214 after 0.09 seconds
[0m01:00:48.381675 [debug] [MainThread]: Sending event: {'category': 'dbt', 'action': 'invocation', 'label': 'end', 'context': [<snowplow_tracker.self_describing_json.SelfDescribingJson object at 0x000001B664F9CC30>, <snowplow_tracker.self_describing_json.SelfDescribingJson object at 0x000001B664D39910>, <snowplow_tracker.self_describing_json.SelfDescribingJson object at 0x000001B664D128B0>]}
[0m01:00:48.382057 [debug] [MainThread]: Flushing usage events
[0m01:00:49.067206 [debug] [MainThread]: An error was encountered while trying to flush usage events
[0m01:01:34.957523 [debug] [MainThread]: Sending event: {'category': 'dbt', 'action': 'invocation', 'label': 'start', 'context': [<snowplow_tracker.self_describing_json.SelfDescribingJson object at 0x000001E4BF510D70>, <snowplow_tracker.self_describing_json.SelfDescribingJson object at 0x000001E4C05FBED0>, <snowplow_tracker.self_describing_json.SelfDescribingJson object at 0x000001E4C05FBD90>]}


============================== 01:01:34.961892 | 0d49643d-5b6f-4a19-998a-9fefafecb060 ==============================
[0m01:01:34.961892 [info ] [MainThread]: Running with dbt=1.9.2
[0m01:01:34.962552 [debug] [MainThread]: running dbt with arguments {'printer_width': '80', 'indirect_selection': 'eager', 'write_json': 'True', 'log_cache_events': 'False', 'partial_parse': 'True', 'cache_selected_only': 'False', 'profiles_dir': 'C:\\Users\\henri\\.dbt', 'debug': 'False', 'warn_error': 'None', 'log_path': 'logs', 'version_check': 'True', 'fail_fast': 'False', 'use_colors': 'True', 'use_experimental_parser': 'False', 'no_print': 'None', 'quiet': 'False', 'empty': 'None', 'warn_error_options': 'WarnErrorOptions(include=[], exclude=[])', 'static_parser': 'True', 'introspect': 'True', 'log_format': 'default', 'target_path': 'None', 'invocation_command': 'dbt debug', 'send_anonymous_usage_stats': 'True'}
[0m01:01:34.979104 [info ] [MainThread]: dbt version: 1.9.2
[0m01:01:34.979530 [info ] [MainThread]: python version: 3.13.1
[0m01:01:34.979934 [info ] [MainThread]: python path: C:\Users\henri\anaconda3\envs\carteira\python.exe
[0m01:01:34.980344 [info ] [MainThread]: os info: Windows-11-10.0.26100-SP0
[0m01:01:35.047682 [info ] [MainThread]: Using profiles dir at C:\Users\henri\.dbt
[0m01:01:35.048251 [info ] [MainThread]: Using profiles.yml file at C:\Users\henri\.dbt\profiles.yml
[0m01:01:35.048647 [info ] [MainThread]: Using dbt_project.yml file at C:\Users\henri\Documents\Projetos\Carteira\dbt_project.yml
[0m01:01:35.049654 [info ] [MainThread]: adapter type: postgres
[0m01:01:35.050067 [info ] [MainThread]: adapter version: 1.9.0
[0m01:01:35.050488 [info ] [MainThread]: Configuration:
[0m01:01:35.050836 [info ] [MainThread]:   profiles.yml file [[32mOK found and valid[0m]
[0m01:01:35.051172 [info ] [MainThread]:   dbt_project.yml file [[31mERROR not found[0m]
[0m01:01:35.051513 [info ] [MainThread]: Required dependencies:
[0m01:01:35.051870 [debug] [MainThread]: Executing "git --help"
[0m01:01:35.082187 [debug] [MainThread]: STDOUT: "b"usage: git [-v | --version] [-h | --help] [-C <path>] [-c <name>=<value>]\n           [--exec-path[=<path>]] [--html-path] [--man-path] [--info-path]\n           [-p | --paginate | -P | --no-pager] [--no-replace-objects] [--no-lazy-fetch]\n           [--no-optional-locks] [--no-advice] [--bare] [--git-dir=<path>]\n           [--work-tree=<path>] [--namespace=<name>] [--config-env=<name>=<envvar>]\n           <command> [<args>]\n\nThese are common Git commands used in various situations:\n\nstart a working area (see also: git help tutorial)\n   clone      Clone a repository into a new directory\n   init       Create an empty Git repository or reinitialize an existing one\n\nwork on the current change (see also: git help everyday)\n   add        Add file contents to the index\n   mv         Move or rename a file, a directory, or a symlink\n   restore    Restore working tree files\n   rm         Remove files from the working tree and from the index\n\nexamine the history and state (see also: git help revisions)\n   bisect     Use binary search to find the commit that introduced a bug\n   diff       Show changes between commits, commit and working tree, etc\n   grep       Print lines matching a pattern\n   log        Show commit logs\n   show       Show various types of objects\n   status     Show the working tree status\n\ngrow, mark and tweak your common history\n   backfill   Download missing objects in a partial clone\n   branch     List, create, or delete branches\n   commit     Record changes to the repository\n   merge      Join two or more development histories together\n   rebase     Reapply commits on top of another base tip\n   reset      Reset current HEAD to the specified state\n   switch     Switch branches\n   tag        Create, list, delete or verify a tag object signed with GPG\n\ncollaborate (see also: git help workflows)\n   fetch      Download objects and refs from another repository\n   pull       Fetch from and integrate with another repository or a local branch\n   push       Update remote refs along with associated objects\n\n'git help -a' and 'git help -g' list available subcommands and some\nconcept guides. See 'git help <command>' or 'git help <concept>'\nto read about a specific subcommand or concept.\nSee 'git help git' for an overview of the system.\n""
[0m01:01:35.082741 [debug] [MainThread]: STDERR: "b''"
[0m01:01:35.083195 [info ] [MainThread]:  - git [[32mOK found[0m]

[0m01:01:35.083673 [info ] [MainThread]: Connection:
[0m01:01:35.084086 [info ] [MainThread]:   host: 127.0.0.1
[0m01:01:35.084452 [info ] [MainThread]:   port: 5433
[0m01:01:35.084800 [info ] [MainThread]:   user: testing
[0m01:01:35.085136 [info ] [MainThread]:   database: inv
[0m01:01:35.085493 [info ] [MainThread]:   schema: public
[0m01:01:35.085869 [info ] [MainThread]:   connect_timeout: 10
[0m01:01:35.086215 [info ] [MainThread]:   role: None
[0m01:01:35.086544 [info ] [MainThread]:   search_path: None
[0m01:01:35.086874 [info ] [MainThread]:   keepalives_idle: 0
[0m01:01:35.087211 [info ] [MainThread]:   sslmode: None
[0m01:01:35.087538 [info ] [MainThread]:   sslcert: None
[0m01:01:35.087882 [info ] [MainThread]:   sslkey: None
[0m01:01:35.088209 [info ] [MainThread]:   sslrootcert: None
[0m01:01:35.088534 [info ] [MainThread]:   application_name: dbt
[0m01:01:35.088863 [info ] [MainThread]:   retries: 1
[0m01:01:35.089416 [info ] [MainThread]: Registered adapter: postgres=1.9.0
[0m01:01:35.328287 [debug] [MainThread]: Acquiring new postgres connection 'debug'
[0m01:01:35.504033 [debug] [MainThread]: Using postgres connection "debug"
[0m01:01:35.504434 [debug] [MainThread]: On debug: select 1 as id
[0m01:01:35.504722 [debug] [MainThread]: Opening a new connection, currently in state init
[0m01:01:35.553878 [debug] [MainThread]: SQL status: SELECT 1 in 0.049 seconds
[0m01:01:35.554832 [debug] [MainThread]: On debug: Close
[0m01:01:35.555193 [info ] [MainThread]:   Connection test: [[32mOK connection ok[0m]

[0m01:01:35.555676 [info ] [MainThread]: [31m1 check failed:[0m
[0m01:01:35.556090 [info ] [MainThread]: Project loading failed for the following reason:
 project path <C:\Users\henri\Documents\Projetos\Carteira\dbt_project.yml> not found

[0m01:01:35.557032 [debug] [MainThread]: Command `dbt debug` failed at 01:01:35.556913 after 0.71 seconds
[0m01:01:35.557358 [debug] [MainThread]: Connection 'debug' was properly closed.
[0m01:01:35.557679 [debug] [MainThread]: Sending event: {'category': 'dbt', 'action': 'invocation', 'label': 'end', 'context': [<snowplow_tracker.self_describing_json.SelfDescribingJson object at 0x000001E4C06EEEA0>, <snowplow_tracker.self_describing_json.SelfDescribingJson object at 0x000001E4C0803650>, <snowplow_tracker.self_describing_json.SelfDescribingJson object at 0x000001E4C06AB570>]}
[0m01:01:35.558060 [debug] [MainThread]: Flushing usage events
[0m01:01:36.246503 [debug] [MainThread]: An error was encountered while trying to flush usage events
